Workbook

Sheet About
A1: Concept map of the note “Voting for a consensus with veto rights” (v0.1)
A3: What it is | B3: Every concept of the note linked to the bibliography, and every bibliography entry linked to the concepts it supports, with the key ideas it conveys.
A4: Concepts to bibliography | B4: One row per concept: the bibliography entries that support it (oldest first), its definition and role in the note, the sections.
A5: Bibliography to concepts | B5: One row per entry (alphabetical): the concepts it supports, the key ideas it conveys, where the note cites it, the full reference, the DOI or URL, and any field still to verify.
A6: Matrix | B6: One row per entry, one column per concept; x where they are linked. Totals by row and column.
A7: How to update | B7: Do not edit this workbook: edit literature/concept-map/concepts.csv and references.csv (each link is entered once, in references.csv), then run python3 tools/concept_map.py from the repository root. Bibliographic details come from manuscript/references.bib; the sections citing each entry are read from manuscript/sections/.
A9: Counts (formulas)
A10: Concepts | B10: =COUNTA('Concepts to bibliography'!E2:E36) -> 35
A11: Bibliography entries | B11: =COUNTA('Bibliography to concepts'!D2:D99) -> 98
A12: Links, counted by concept | B12: =SUM('Concepts to bibliography'!F2:F36) -> 163
A13: Links, counted by entry | B13: =SUM('Bibliography to concepts'!I2:I99) -> 163
A14: Links in the matrix | B14: =COUNTIF(Matrix!C3:AK100,"x") -> 163
A15: Reciprocity check | B15: =IF(AND(B12=B13,B13=B14),"OK: both directions agree","MISMATCH") -> OK: both directions agree

Sheet Concepts to bibliography
A1: Concept | B1: Bibliography entries | C1: Definition and role in the note | D1: Note sections | E1: Concept id | F1: Number of entries
A2: Condorcet winner and the majority principle | B2: Condorcet (1785). Essai sur l'application de l'analyse à la probabilité des décisions rendues à la pluralité des voix Black (1948). On the Rationale of Group Decision-Making May (1952). A Set of Independent Necessary and Sufficient Conditions for Simple Majority Decision Rae (1969). Decision-Rules and Individual Values in Constitutional Choice Young & Levenglick (1978). A Consistent Extension of Condorcet's Election Principle Moulin (1988). Condorcet's Principle Implies the No Show Paradox Young (1988). Condorcet's Theory of Voting | C2: An option that beats every other option in pairwise majority. The majoritarian reading of a compromise, and the second step of QVC. | D2: 2.2, 2.5, 3.3, 5, 6 | E2: C01 | F2: =COUNTIF(INDEX(Matrix!$C$3:$AK$100,0,MATCH(E2,Matrix!$C$2:$AK$2,0)),"x") -> 7
A3: Majority cycles and their frequency | B3: Condorcet (1785). Essai sur l'application de l'analyse à la probabilité des décisions rendues à la pluralité des voix Guilbaud (1952). Les théories de l'intérêt général et le problème logique de l'agrégation Gehrlein & Fishburn (1976). The Probability of the Paradox of Voting: A Computable Solution Gehrlein (2006). Condorcet's Paradox Regenwetter et al. (2006). Behavioral Social Choice: Probabilistic Models, Statistical Inference, and Applications Tideman (2006). Collective Decisions and Voting: The Potential for Public Choice Tideman & Plassmann (2012). Modeling the Outcomes of Vote-Casting in Actual Elections | C3: Majority preferences can be cyclic (Condorcet paradox); how often a Condorcet winner exists depends on the structure of preferences. | D3: 3.2, Table 1 | E3: C02 | F3: =COUNTIF(INDEX(Matrix!$C$3:$AK$100,0,MATCH(E3,Matrix!$C$2:$AK$2,0)),"x") -> 7
A4: Smith set and Condorcet completions | B4: Smith (1973). Aggregation of Preferences with Variable Electorate Fishburn (1977). Condorcet Social Choice Functions Laffond et al. (1993). The Bipartisan Set of a Tournament Game Schulze (2011). A New Monotonic, Clone-Independent, Reversal Symmetric, and Condorcet-Consistent Single-Winner Election Method Brandt et al. (2016). Handbook of Computational Social Choice | C4: The smallest set of options that each beat every option outside it; Condorcet methods differ in how they choose within it. | D4: 2.2, 5.1 | E4: C03 | F4: =COUNTIF(INDEX(Matrix!$C$3:$AK$100,0,MATCH(E4,Matrix!$C$2:$AK$2,0)),"x") -> 5
A5: Schulze method | B5: Schulze (2011). A New Monotonic, Clone-Independent, Reversal Symmetric, and Condorcet-Consistent Single-Winner Election Method Debian Project (2022). Constitution for the Debian Project (v1.9) | C5: Condorcet method based on the strongest paths of pairwise victories: Smith-consistent, clone-independent, monotonic, O(m^3). The majority step of QVC. | D5: 5, 6, App. B | E5: C04 | F5: =COUNTIF(INDEX(Matrix!$C$3:$AK$100,0,MATCH(E5,Matrix!$C$2:$AK$2,0)),"x") -> 2
A6: Ranked Pairs | B6: Tideman (1987). Independence of Clones as a Criterion for Voting Rules Zavist & Tideman (1989). Complete Independence of Clones in the Ranked Pairs Rule Tideman (2006). Collective Decisions and Voting: The Potential for Public Choice | C6: Locks pairwise majorities from the strongest down unless they close a cycle; clone-independent. Could replace Schulze in QVC. | D6: 5, App. B | E6: C05 | F6: =COUNTIF(INDEX(Matrix!$C$3:$AK$100,0,MATCH(E6,Matrix!$C$2:$AK$2,0)),"x") -> 3
A7: Split Cycle and Stable Voting | B7: Holliday & Pacuit (2023). Split Cycle: A New Condorcet-Consistent Voting Method Independent of Clones and Immune to Spoilers Holliday & Pacuit (2023). Stable Voting | C7: Discards the weakest majority in every cycle; clone-independent and immune to spoilers, but often not single-winner. Stable Voting refines it to one winner. | D7: 5, App. B | E7: C06 | F7: =COUNTIF(INDEX(Matrix!$C$3:$AK$100,0,MATCH(E7,Matrix!$C$2:$AK$2,0)),"x") -> 2
A8: Kemeny-Young and distance-based consensus | B8: Kemeny (1959). Mathematics without Numbers Young & Levenglick (1978). A Consistent Extension of Condorcet's Election Principle Young (1988). Condorcet's Theory of Voting Bartholdi et al. (1989). Voting Schemes for Which It Can Be Difficult to Tell Who Won the Election Elkind et al. (2015). Distance Rationalization of Voting Rules Brandt et al. (2016). Handbook of Computational Social Choice | C8: The ranking closest to the voters' pairwise preferences; more generally, rules read as the nearest consensus profile. Kemeny is NP-hard. | D8: 2.5, 5.1 | E8: C07 | F8: =COUNTIF(INDEX(Matrix!$C$3:$AK$100,0,MATCH(E8,Matrix!$C$2:$AK$2,0)),"x") -> 6
A9: Copeland and Minimax | B9: Simpson (1969). On Defining Areas of Voter Choice: Professor Tullock on Stable Voting Fishburn (1977). Condorcet Social Choice Functions | C9: Condorcet methods that count pairwise wins (Copeland) or minimise the worst defeat (Minimax); neither is independent of clones. | D9: 5 | E9: C08 | F9: =COUNTIF(INDEX(Matrix!$C$3:$AK$100,0,MATCH(E9,Matrix!$C$2:$AK$2,0)),"x") -> 2
A10: Positional and runoff rules | B10: Young (1974). An Axiomatization of Borda's Rule Merrill (1984). A Comparison of Efficiency of Multicandidate Electoral Systems Tideman (1987). Independence of Clones as a Criterion for Voting Rules Felsenthal (2012). Review of Paradoxes Afflicting Procedures for Electing a Single Candidate Laslier (2012). And the Loser Is… Plurality Voting | C10: Plurality, Borda and instant-runoff (IRV): score ranks or eliminate by first choices. Vote splitting (plurality), teaming (Borda), non-monotonicity (IRV). | D10: 5, 7 | E10: C09 | F10: =COUNTIF(INDEX(Matrix!$C$3:$AK$100,0,MATCH(E10,Matrix!$C$2:$AK$2,0)),"x") -> 5
A11: Evaluative rules: approval and Majority Judgment | B11: Brams & Fishburn (1978). Approval Voting Balinski & Laraki (2007). A Theory of Measuring, Electing, and Ranking Felsenthal & Machover (2008). The Majority Judgement Voting Procedure: A Critical Evaluation Laslier & Sanver (2010). Handbook on Approval Voting Balinski & Laraki (2011). Majority Judgment: Measuring, Ranking, and Electing Laslier (2012). And the Loser Is… Plurality Voting | C11: Voters approve or grade options; approval elects the most acceptable option, Majority Judgment the best median grade. The acceptability line of the QVC ballot borrows from them. | D11: 2.1, 5.1 | E11: C10 | F11: =COUNTIF(INDEX(Matrix!$C$3:$AK$100,0,MATCH(E11,Matrix!$C$2:$AK$2,0)),"x") -> 6
A12: Probabilistic social choice | B12: Fishburn (1984). Probabilistic Social Choice Based on Simple Voting Comparisons Laffond et al. (1993). The Bipartisan Set of a Tournament Game Brandl et al. (2016). Consistent Probabilistic Social Choice | C12: Maximal lotteries and tournament solutions: lotteries over options unbeaten in expected pairwise majority. | D12: 5.1 | E12: C11 | F12: =COUNTIF(INDEX(Matrix!$C$3:$AK$100,0,MATCH(E12,Matrix!$C$2:$AK$2,0)),"x") -> 3
A13: Independence of clones and agenda flooding | B13: Tideman (1987). Independence of Clones as a Criterion for Voting Rules Zavist & Tideman (1989). Complete Independence of Clones in the Ranked Pairs Rule Schulze (2011). A New Monotonic, Clone-Independent, Reversal Symmetric, and Condorcet-Consistent Single-Winner Election Method Felsenthal (2012). Review of Paradoxes Afflicting Procedures for Electing a Single Candidate Holliday & Pacuit (2023). Split Cycle: A New Condorcet-Consistent Voting Method Independent of Clones and Immune to Spoilers | C13: Adding variants of an option must not change the outcome. Required by an open agenda (H1); fails for Borda, fallback bargaining and the proportional veto core. | D13: 2.3, 5.2, Prop. 3 and 7, Table 7 | E13: C12 | F13: =COUNTIF(INDEX(Matrix!$C$3:$AK$100,0,MATCH(E13,Matrix!$C$2:$AK$2,0)),"x") -> 5
... A36: Delegation in veto bargaining | B36: Kartik et al. (2021). Delegation in Veto Bargaining | C36: Under incomplete information, the best use of a veto player can be to let them choose within an interval fixed in advance. | D36: 4.2 | E36: C35 | F36: =COUNTIF(INDEX(Matrix!$C$3:$AK$100,0,MATCH(E36,Matrix!$C$2:$AK$2,0)),"x") -> 1

Sheet Bibliography to concepts
A1: Bibliography entry | B1: Concepts used | C1: Key ideas conveyed | D1: Citation key | E1: Cited in (sections of the note) | F1: Full reference | G1: DOI or URL | H1: Still to verify | I1: Number of concepts
A2: Agranov & Tergiman (2019). Communication in Bargaining Games with Unanimity | B2: C33 Communication, accountability and experiments in committees C20 Unanimity versus majority with veto | C2: Experiments on communication before voting in bargaining games with unanimity. | D2: AgranovTergiman2019 | E2: §4 Veto literature | F2: Agranov, M. & Tergiman, C. (2019). Communication in Bargaining Games with Unanimity. Experimental Economics 22(2): 350–368. | G2: https://doi.org/10.1007/s10683-018-9571-6 | I2: =COUNTIF(INDEX(Matrix!$C$3:$AK$100,MATCH(D2,Matrix!$B$3:$B$100,0),0),"x") -> 2
A3: Anbarci (1993). Noncooperative Foundations of the Area Monotonic Solution | B3: C29 Two-party compromise rules C25 Voting by veto (sequential vetoes) | C3: Alternating vetoes give non-cooperative foundations to the area-monotonic bargaining solution. | D3: Anbarci1993 | E3: §4 Veto literature | F3: Anbarci, N. (1993). Noncooperative Foundations of the Area Monotonic Solution. Quarterly Journal of Economics 108(1): 245–258. | G3: https://doi.org/10.2307/2118502 | I3: =COUNTIF(INDEX(Matrix!$C$3:$AK$100,MATCH(D3,Matrix!$B$3:$B$100,0),0),"x") -> 2
A4: Anesi & Bowen (2021). Policy Experimentation in Committees: A Case against Veto Rights under Redistributive Constraints | B4: C21 Veto players, status-quo bias and gridlock C23 Dynamic bargaining and endogenous status quo | C4: Veto rights deter policy experimentation under redistributive constraints: a case against vetoes. | D4: AnesiBowen2021 | E4: §4 Veto literature | F4: Anesi, V. & Bowen, T. R. (2021). Policy Experimentation in Committees: A Case against Veto Rights under Redistributive Constraints. American Economic Journal: Microeconomics 13(3): 124–162. | G4: https://doi.org/10.1257/mic.20190023 | I4: =COUNTIF(INDEX(Matrix!$C$3:$AK$100,MATCH(D4,Matrix!$B$3:$B$100,0),0),"x") -> 2
A5: Anesi & Duggan (2017). Dynamic Bargaining and Stability with Veto Players | B5: C23 Dynamic bargaining and endogenous status quo C21 Veto players, status-quo bias and gridlock | C5: Stability of policies in dynamic bargaining with veto players. | D5: AnesiDuggan2017 | E5: §4 Veto literature | F5: Anesi, V. & Duggan, J. (2017). Dynamic Bargaining and Stability with Veto Players. Games and Economic Behavior 103: 30–40. | G5: https://doi.org/10.1016/j.geb.2016.04.010 | I5: =COUNTIF(INDEX(Matrix!$C$3:$AK$100,MATCH(D5,Matrix!$B$3:$B$100,0),0),"x") -> 2
A6: Anesi & Seidmann (2015). Bargaining in Standing Committees with an Endogenous Default | B6: C23 Dynamic bargaining and endogenous status quo | C6: Bargaining in standing committees whose default option is the previous decision: dynamics and inefficiency. | D6: AnesiSeidmann2015 | E6: §4 Veto literature | F6: Anesi, V. & Seidmann, D. J. (2015). Bargaining in Standing Committees with an Endogenous Default. Review of Economic Studies 82(3): 825–867. | G6: https://doi.org/10.1093/restud/rdv009 | I6: =COUNTIF(INDEX(Matrix!$C$3:$AK$100,MATCH(D6,Matrix!$B$3:$B$100,0),0),"x") -> 1
A7: Arrow (1951). Social Choice and Individual Values | B7: C13 Impossibility theorems | C7: No rule turning individual rankings into a social ranking satisfies Pareto, independence of irrelevant alternatives and non-dictatorship when there are three options or more. | D7: Arrow1951 | E7: §3 Limits | F7: Arrow, K. J. (1951). Social Choice and Individual Values. John Wiley & Sons. | G7: https://www.loc.gov/item/51009755/ | I7: =COUNTIF(INDEX(Matrix!$C$3:$AK$100,MATCH(D7,Matrix!$B$3:$B$100,0),0),"x") -> 1
A8: Balinski & Laraki (2007). A Theory of Measuring, Electing, and Ranking | B8: C10 Evaluative rules: approval and Majority Judgment | C8: Majority Judgment: voters grade every candidate on a common scale, and candidates are ranked by their median grade. | D8: BalinskiLaraki2007 | E8: §2 Setting, §5 Aggregation | F8: Balinski, M. & Laraki, R. (2007). A Theory of Measuring, Electing, and Ranking. Proceedings of the National Academy of Sciences 104(21): 8720–8725. | G8: https://doi.org/10.1073/pnas.0702634104 | I8: =COUNTIF(INDEX(Matrix!$C$3:$AK$100,MATCH(D8,Matrix!$B$3:$B$100,0),0),"x") -> 1
A9: Balinski & Laraki (2011). Majority Judgment: Measuring, Ranking, and Electing | B9: C10 Evaluative rules: approval and Majority Judgment | C9: Book-length theory of Majority Judgment: measuring, ranking and electing with grades. | D9: BalinskiLaraki2011 | E9: §2 Setting, §5 Aggregation | F9: Balinski, M. & Laraki, R. (2011). Majority Judgment: Measuring, Ranking, and Electing. MIT Press. | G9: https://doi.org/10.7551/mitpress/9780262015134.001.0001 | I9: =COUNTIF(INDEX(Matrix!$C$3:$AK$100,MATCH(D9,Matrix!$B$3:$B$100,0),0),"x") -> 1
A10: Barberà & Coelho (2017). Balancing the Power to Appoint Officers | B10: C29 Two-party compromise rules | C10: Shortlisting procedures to balance two parties' power when appointing an officer. | D10: BarberaCoelho2017 | E10: §4 Veto literature | F10: Barberà, S. & Coelho, D. (2017). Balancing the Power to Appoint Officers. Games and Economic Behavior 101: 189–203. | G10: https://doi.org/10.1016/j.geb.2015.10.005 | I10: =COUNTIF(INDEX(Matrix!$C$3:$AK$100,MATCH(D10,Matrix!$B$3:$B$100,0),0),"x") -> 1
A11: Barberà & Coelho (2022). Compromising on Compromise Rules | B11: C29 Two-party compromise rules | C11: Compares compromise rules between two parties, such as shortlisting, and their strategic properties. | D11: BarberaCoelho2022 | E11: §4 Veto literature, §8 Discussion | F11: Barberà, S. & Coelho, D. (2022). Compromising on Compromise Rules. RAND Journal of Economics 53(1): 95–112. | G11: https://doi.org/10.1111/1756-2171.12401 | I11: =COUNTIF(INDEX(Matrix!$C$3:$AK$100,MATCH(D11,Matrix!$B$3:$B$100,0),0),"x") -> 1
A12: Barberà & Gerber (2017). Sequential Voting and Agenda Manipulation | B12: C22 Agenda setting and proposal power C17 Spatial voting, chaos and agenda control | C12: Sequential voting procedures are open to agenda manipulation. | D12: BarberaGerber2017 | E12: §4 Veto literature, §5 Aggregation | F12: Barberà, S. & Gerber, A. (2017). Sequential Voting and Agenda Manipulation. Theoretical Economics 12(1): 211–247. | G12: https://doi.org/10.3982/TE2118 | I12: =COUNTIF(INDEX(Matrix!$C$3:$AK$100,MATCH(D12,Matrix!$B$3:$B$100,0),0),"x") -> 2
A13: Baron & Ferejohn (1989). Bargaining in Legislatures | B13: C22 Agenda setting and proposal power C23 Dynamic bargaining and endogenous status quo | C13: Legislative bargaining with random recognition: proposers capture a large share, depending on the voting rule and the members' patience. | D13: BaronFerejohn1989 | E13: §4 Veto literature, §5 Aggregation | F13: Baron, D. P. & Ferejohn, J. A. (1989). Bargaining in Legislatures. American Political Science Review 83(4): 1181–1206. | G13: https://doi.org/10.2307/1961664 | I13: =COUNTIF(INDEX(Matrix!$C$3:$AK$100,MATCH(D13,Matrix!$B$3:$B$100,0),0),"x") -> 2
... A73: Moulin (1982). Voting with Proportional Veto Power | B73: C26 Proportional veto and the veto core C25 Voting by veto (sequential vetoes) | C73: Neutral rules implementable in strong equilibrium need veto power distributed roughly in proportion to coalition size; voting by successive veto is an example. | D73: Moulin1982 | E73: §2 Setting, §4 Veto literature, §6 Procedure | F73: Moulin, H. (1982). Voting with Proportional Veto Power. Econometrica 50(1): 145–162. | G73: https://doi.org/10.2307/1912535 | I73: =COUNTIF(INDEX(Matrix!$C$3:$AK$100,MATCH(D73,Matrix!$B$3:$B$100,0),0),"x") -> 2
A74: Moulin (1983). The Strategy of Social Choice | B74: C26 Proportional veto and the veto core C25 Voting by veto (sequential vetoes) C13 Impossibility theorems | C74: Textbook on the strategy of social choice: manipulation, implementation and veto procedures. | D74: Moulin1983 | E74: §4 Veto literature | F74: Moulin, H. (1983). The Strategy of Social Choice. North-Holland. | I74: =COUNTIF(INDEX(Matrix!$C$3:$AK$100,MATCH(D74,Matrix!$B$3:$B$100,0),0),"x") -> 3
A75: Moulin (1988). Condorcet's Principle Implies the No Show Paradox | B75: C15 Participation and the no-show paradox C01 Condorcet winner and the majority principle | C75: Every Condorcet-consistent rule violates participation (the no-show paradox) when there are four options or more. | D75: Moulin1988noshow | E75: §3 Limits | F75: Moulin, H. (1988). Condorcet's Principle Implies the No Show Paradox. Journal of Economic Theory 45(1): 53–64. | G75: https://doi.org/10.1016/0022-0531(88)90253-0 | I75: =COUNTIF(INDEX(Matrix!$C$3:$AK$100,MATCH(D75,Matrix!$B$3:$B$100,0),0),"x") -> 2
A76: Mueller (1978). Voting by Veto | B76: C25 Voting by veto (sequential vetoes) | C76: Voting by veto: each member proposes one option, the status quo is added, and members strike options in turn; it always decides and no member gets their worst outcome. | D76: Mueller1978 | E76: §4 Veto literature | F76: Mueller, D. C. (1978). Voting by Veto. Journal of Public Economics 10(1): 57–75. | G76: https://doi.org/10.1016/0047-2727(78)90005-1 | I76: =COUNTIF(INDEX(Matrix!$C$3:$AK$100,MATCH(D76,Matrix!$B$3:$B$100,0),0),"x") -> 1
A77: Nakamura (1979). The Vetoers in a Simple Game with Ordinal Preferences | B77: C18 Supermajority, stability and the core C21 Veto players, status-quo bias and gridlock | C77: The core of a simple game is non-empty for all preference profiles if and only if there are fewer options than the Nakamura number; with a veto player, the core is never empty. | D77: Nakamura1979 | E77: §3 Limits | F77: Nakamura, K. (1979). The Vetoers in a Simple Game with Ordinal Preferences. International Journal of Game Theory 8(1): 55–61. | G77: https://doi.org/10.1007/BF01763051 | I77: =COUNTIF(INDEX(Matrix!$C$3:$AK$100,MATCH(D77,Matrix!$B$3:$B$100,0),0),"x") -> 2
A78: Nunnari (2021). Dynamic Legislative Bargaining with Veto Power: Theory and Experiments | B78: C23 Dynamic bargaining and endogenous status quo C21 Veto players, status-quo bias and gridlock C33 Communication, accountability and experiments in committees | C78: Dynamic bargaining with a veto player, theory and experiments: the vetoer's power grows over rounds. | D78: Nunnari2021 | E78: §4 Veto literature, §6 Procedure | F78: Nunnari, S. (2021). Dynamic Legislative Bargaining with Veto Power: Theory and Experiments. Games and Economic Behavior 126: 186–230. | G78: https://doi.org/10.1016/j.geb.2020.11.006 | I78: =COUNTIF(INDEX(Matrix!$C$3:$AK$100,MATCH(D78,Matrix!$B$3:$B$100,0),0),"x") -> 3
A79: Piazolo & Vanberg (2025). Legislative Bargaining with Private Information: A Comparison of Majority and Unanimity Rule | B79: C20 Unanimity versus majority with veto C33 Communication, accountability and experiments in committees | C79: Majority against unanimity with private information: unanimity brings more delay and costlier bargaining. | D79: PiazoloVanberg2025 | E79: §4 Veto literature | F79: Piazolo, D. & Vanberg, C. (2025). Legislative Bargaining with Private Information: A Comparison of Majority and Unanimity Rule. Games and Economic Behavior 153: 499–522. | G79: https://doi.org/10.1016/j.geb.2025.07.010 | I79: =COUNTIF(INDEX(Matrix!$C$3:$AK$100,MATCH(D79,Matrix!$B$3:$B$100,0),0),"x") -> 2
A80: Plott (1967). A Notion of Equilibrium and Its Possibility Under Majority Rule | B80: C17 Spatial voting, chaos and agenda control C18 Supermajority, stability and the core | C80: A majority-rule equilibrium in several dimensions needs very restrictive symmetry of preferences, so it generally fails to exist. | D80: Plott1967 | E80: §3 Limits | F80: Plott, C. R. (1967). A Notion of Equilibrium and Its Possibility Under Majority Rule. American Economic Review 57(4): 787–806. | G80: https://www.jstor.org/stable/1815369 | I80: =COUNTIF(INDEX(Matrix!$C$3:$AK$100,MATCH(D80,Matrix!$B$3:$B$100,0),0),"x") -> 2
A81: Rae (1969). Decision-Rules and Individual Values in Constitutional Choice | B81: C19 Choice of the voting quota C01 Condorcet winner and the majority principle | C81: Simple majority maximises a voter's expected agreement with collective decisions when the voter does not know their future preferences. | D81: Rae1969 | E81: §3 Limits | F81: Rae, D. W. (1969). Decision-Rules and Individual Values in Constitutional Choice. American Political Science Review 63(1): 40–56. | G81: https://doi.org/10.2307/1954283 | I81: =COUNTIF(INDEX(Matrix!$C$3:$AK$100,MATCH(D81,Matrix!$B$3:$B$100,0),0),"x") -> 2
A82: Regenwetter et al. (2006). Behavioral Social Choice: Probabilistic Models, Statistical Inference, and Applications | B82: C02 Majority cycles and their frequency C32 Evaluating rules with simulations and data | C82: Behavioural social choice: majority cycles are rare in real election data; the impartial culture overstates them. | D82: RegenwetterEtAl2006 | E82: §3 Limits, §4 Veto literature | F82: Regenwetter, M., Grofman, B., Marley, A. A. J. & Tsetlin, I. (2006). Behavioral Social Choice: Probabilistic Models, Statistical Inference, and Applications. Cambridge University Press. | G82: https://www.loc.gov/item/2005023291/ | I82: =COUNTIF(INDEX(Matrix!$C$3:$AK$100,MATCH(D82,Matrix!$B$3:$B$100,0),0),"x") -> 2
A83: Resnick (2014). On Consensus and Humming in the IETF | B83: C30 Consensus decision-making in practice | C83: IETF rough consensus: lack of disagreement matters more than agreement; consensus is reached when all objections are addressed, not necessarily accommodated. | D83: Resnick2014rfc7282 | E83: §4 Veto literature, §6 Procedure, §8 Discussion | F83: Resnick, P. (2014). On Consensus and Humming in the IETF. RFC Editor. | G83: https://doi.org/10.17487/RFC7282 | I83: =COUNTIF(INDEX(Matrix!$C$3:$AK$100,MATCH(D83,Matrix!$B$3:$B$100,0),0),"x") -> 1
A84: Roháč (2008). The Unanimity Rule and Religious Fractionalisation in the Polish-Lithuanian Republic | B84: C31 Institutional design of vetoes C21 Veto players, status-quo bias and gridlock | C84: The liberum veto (unanimity) of the Polish-Lithuanian Sejm, linked to religious fractionalisation, paralysed decision-making. | D84: Rohac2008 | E84: §1 Introduction, §4 Veto literature | F84: Roháč, D. (2008). The Unanimity Rule and Religious Fractionalisation in the Polish-Lithuanian Republic. Constitutional Political Economy 19(2): 111–128. | G84: https://doi.org/10.1007/s10602-008-9037-5 | I84: =COUNTIF(INDEX(Matrix!$C$3:$AK$100,MATCH(D84,Matrix!$B$3:$B$100,0),0),"x") -> 2
A85: Romer & Rosenthal (1978). Political Resource Allocation, Controlled Agendas, and the Status Quo | B85: C22 Agenda setting and proposal power C21 Veto players, status-quo bias and gridlock | C85: An agenda setter making take-it-or-leave-it proposals extracts more the worse the reversion point (status quo) is for the voters. | D85: RomerRosenthal1978 | E85: §4 Veto literature | F85: Romer, T. & Rosenthal, H. (1978). Political Resource Allocation, Controlled Agendas, and the Status Quo. Public Choice 33(4): 27–43. | G85: https://doi.org/10.1007/BF03187594 | I85: =COUNTIF(INDEX(Matrix!$C$3:$AK$100,MATCH(D85,Matrix!$B$3:$B$100,0),0),"x") -> 2
A86: Satterthwaite (1975). Strategy-Proofness and Arrow's Conditions: Existence and Correspondence Theorems for Voting Procedures and Social Welfare Functions | B86: C13 Impossibility theorems C14 Manipulation and its complexity | C86: Proves the same strategy-proofness impossibility independently and shows its correspondence with Arrow's theorem. | D86: Satterthwaite1975 | E86: §1 Introduction, §3 Limits, §4 Veto literature | F86: Satterthwaite, M. A. (1975). Strategy-Proofness and Arrow's Conditions: Existence and Correspondence Theorems for Voting Procedures and Social Welfare Functions. Journal of Economic Theory 10(2): 187–217. | G86: https://doi.org/10.1016/0022-0531(75)90050-2 | I86: =COUNTIF(INDEX(Matrix!$C$3:$AK$100,MATCH(D86,Matrix!$B$3:$B$100,0),0),"x") -> 2
... A99: Zavist & Tideman (1989). Complete Independence of Clones in the Ranked Pairs Rule | B99: C05 Ranked Pairs C12 Independence of clones and agenda flooding | C99: A tie-breaking refinement makes Ranked Pairs completely independent of clones. | D99: ZavistTideman1989 | E99: §5 Aggregation | F99: Zavist, T. M. & Tideman, T. N. (1989). Complete Independence of Clones in the Ranked Pairs Rule. Social Choice and Welfare 6(2): 167–173. | G99: https://doi.org/10.1007/BF00303170 | I99: =COUNTIF(INDEX(Matrix!$C$3:$AK$100,MATCH(D99,Matrix!$B$3:$B$100,0),0),"x") -> 2

Sheet Matrix
A1: Bibliography entry | B1: Citation key | C1: Condorcet winner and the majority principle | D1: Majority cycles and their frequency | E1: Smith set and Condorcet completions | F1: Schulze method | G1: Ranked Pairs | H1: Split Cycle and Stable Voting | I1: Kemeny-Young and distance-based consensus | J1: Copeland and Minimax | K1: Positional and runoff rules | L1: Evaluative rules: approval and Majority Judgment | M1: Probabilistic social choice | N1: Independence of clones and agenda flooding | O1: Impossibility theorems | P1: Manipulation and its complexity | Q1: Participation and the no-show paradox | R1: Single-peaked preferences and the median voter | S1: Spatial voting, chaos and agenda control | T1: Supermajority, stability and the core | U1: Choice of the voting quota | V1: Unanimity versus majority with veto | W1: Veto players, status-quo bias and gridlock | X1: Agenda setting and proposal power | Y1: Dynamic bargaining and endogenous status quo | Z1: Number of rounds and fast proposal procedures | AA1: Voting by veto (sequential vetoes) | AB1: Proportional veto and the veto core | AC1: Majority power versus veto power | AD1: Compromise by descent: fallback bargaining and majoritarian compromise | AE1: Two-party compromise rules | AF1: Consensus decision-making in practice | AG1: Institutional design of vetoes | AH1: Evaluating rules with simulations and data | AI1: Communication, accountability and experiments in committees | AJ1: Veto budgets and storable votes | AK1: Delegation in veto bargaining | AL1: Number of concepts
B2: Concept id | C2: C01 | D2: C02 | E2: C03 | F2: C04 | G2: C05 | H2: C06 | I2: C07 | J2: C08 | K2: C09 | L2: C10 | M2: C11 | N2: C12 | O2: C13 | P2: C14 | Q2: C15 | R2: C16 | S2: C17 | T2: C18 | U2: C19 | V2: C20 | W2: C21 | X2: C22 | Y2: C23 | Z2: C24 | AA2: C25 | AB2: C26 | AC2: C27 | AD2: C28 | AE2: C29 | AF2: C30 | AG2: C31 | AH2: C32 | AI2: C33 | AJ2: C34 | AK2: C35
A3: Agranov & Tergiman (2019) | B3: AgranovTergiman2019 | V3: x | AI3: x | AL3: =COUNTIF(C3:AK3,"x") -> 2
A4: Anbarci (1993) | B4: Anbarci1993 | AA4: x | AE4: x | AL4: =COUNTIF(C4:AK4,"x") -> 2
A5: Anesi & Bowen (2021) | B5: AnesiBowen2021 | W5: x | Y5: x | AL5: =COUNTIF(C5:AK5,"x") -> 2
A6: Anesi & Duggan (2017) | B6: AnesiDuggan2017 | W6: x | Y6: x | AL6: =COUNTIF(C6:AK6,"x") -> 2
A7: Anesi & Seidmann (2015) | B7: AnesiSeidmann2015 | Y7: x | AL7: =COUNTIF(C7:AK7,"x") -> 1
A8: Arrow (1951) | B8: Arrow1951 | O8: x | AL8: =COUNTIF(C8:AK8,"x") -> 1
A9: Balinski & Laraki (2007) | B9: BalinskiLaraki2007 | L9: x | AL9: =COUNTIF(C9:AK9,"x") -> 1
A10: Balinski & Laraki (2011) | B10: BalinskiLaraki2011 | L10: x | AL10: =COUNTIF(C10:AK10,"x") -> 1
A11: Barberà & Coelho (2017) | B11: BarberaCoelho2017 | AE11: x | AL11: =COUNTIF(C11:AK11,"x") -> 1
A12: Barberà & Coelho (2022) | B12: BarberaCoelho2022 | AE12: x | AL12: =COUNTIF(C12:AK12,"x") -> 1
A13: Barberà & Gerber (2017) | B13: BarberaGerber2017 | S13: x | X13: x | AL13: =COUNTIF(C13:AK13,"x") -> 2
A14: Baron & Ferejohn (1989) | B14: BaronFerejohn1989 | X14: x | Y14: x | AL14: =COUNTIF(C14:AK14,"x") -> 2
A15: Bartholdi et al. (1989) | B15: BartholdiToveyTrick1989hard | I15: x | P15: x | AL15: =COUNTIF(C15:AK15,"x") -> 2
A16: Bartholdi et al. (1989) | B16: BartholdiToveyTrick1989manip | P16: x | AL16: =COUNTIF(C16:AK16,"x") -> 1
A17: Black (1948) | B17: Black1948 | C17: x | R17: x | AL17: =COUNTIF(C17:AK17,"x") -> 2
A18: Bognar et al. (2015) | B18: Bognar2015 | Z18: x | AL18: =COUNTIF(C18:AK18,"x") -> 1
A19: Bouton et al. (2017) | B19: BoutonLlorenteSaguerMalherbe2017 | V19: x | AI19: x | AL19: =COUNTIF(C19:AK19,"x") -> 2
A20: Bouton et al. (2018) | B20: BoutonLlorenteSaguerMalherbe2018 | V20: x | AL20: =COUNTIF(C20:AK20,"x") -> 1
A21: Brams & Fishburn (1978) | B21: BramsFishburn1978 | L21: x | AL21: =COUNTIF(C21:AK21,"x") -> 1
A22: Brams & Kilgour (2001) | B22: BramsKilgour2001 | AD22: x | AL22: =COUNTIF(C22:AK22,"x") -> 1
A23: Brandl et al. (2016) | B23: BrandlBrandtSeedig2016 | M23: x | AL23: =COUNTIF(C23:AK23,"x") -> 1
A24: Brandt et al. (2016) | B24: BrandtEtAl2016handbook | E24: x | I24: x | P24: x | AL24: =COUNTIF(C24:AK24,"x") -> 3
A25: Brandt et al. (2017) | B25: BrandtGeistPeters2017 | Q25: x | AL25: =COUNTIF(C25:AK25,"x") -> 1
A26: Breitmoser & Valasek (2024) | B26: BreitmoserValasek2024 | V26: x | AI26: x | AL26: =COUNTIF(C26:AK26,"x") -> 2
A27: Buchanan & Tullock (1962) | B27: BuchananTullock1962 | U27: x | W27: x | AL27: =COUNTIF(C27:AK27,"x") -> 2
A28: Cailloux et al. (2023) | B28: CaillouxNapolitanoSanver2022 | AD28: x | AE28: x | AL28: =COUNTIF(C28:AK28,"x") -> 2
A29: Caplin & Nalebuff (1988) | B29: CaplinNalebuff1988 | T29: x | U29: x | AL29: =COUNTIF(C29:AK29,"x") -> 2
A30: Casella (2005) | B30: Casella2005 | AJ30: x | AL30: =COUNTIF(C30:AK30,"x") -> 1
A31: Condorcet (1785) | B31: Condorcet1785 | C31: x | D31: x | AL31: =COUNTIF(C31:AK31,"x") -> 2
A32: Debian Project (2022) | B32: Debian2024constitution | F32: x | AG32: x | AL32: =COUNTIF(C32:AK32,"x") -> 2
A33: Dziuda & Loeper (2016) | B33: DziudaLoeper2016 | W33: x | Y33: x | AL33: =COUNTIF(C33:AK33,"x") -> 2
A34: Elkind et al. (2015) | B34: ElkindFaliszewskiSlinko2015 | I34: x | AL34: =COUNTIF(C34:AK34,"x") -> 1
A35: European Union (2016) | B35: TEU2016art16 | AG35: x | AL35: =COUNTIF(C35:AK35,"x") -> 1
A36: Faliszewski & Procaccia (2010) | B36: FaliszewskiProcaccia2010 | P36: x | AL36: =COUNTIF(C36:AK36,"x") -> 1
A37: Felsenthal & Machover (2008) | B37: FelsenthalMachover2008 | L37: x | P37: x | AL37: =COUNTIF(C37:AK37,"x") -> 2
A38: Felsenthal (2012) | B38: Felsenthal2012review | K38: x | N38: x | Q38: x | AL38: =COUNTIF(C38:AK38,"x") -> 3
A39: Fishburn (1977) | B39: Fishburn1977 | E39: x | J39: x | AL39: =COUNTIF(C39:AK39,"x") -> 2
A40: Fishburn (1984) | B40: Fishburn1984 | M40: x | AL40: =COUNTIF(C40:AK40,"x") -> 1
...
